<?xml version="1.0"?>
<robot xmlns:xacro="http://www.ros.org/wiki/xacro">

	<xacro:include filename="inertial_macros.xacro"/>

	<material name="white">
   		<color rgba="1 1 1 1"/>
  	</material>
  	
  	<material name="orange">
   		<color rgba="1 0.3 0.1 1"/>
  	</material>

	<material name="red">
   		<color rgba="1 0 0 1"/>
  	</material>

	<material name="blue">
   		<color rgba="0.2 0.2 1 1"/>
  	</material>

	<material name="green">
   		<color rgba="0 0.84 0 1"/>
  	</material>

	<material name="black">
   		<color rgba="0 0 0 1"/>
  	</material>
  	
  	<material name="grey">
   		<color rgba="0.5 0.5 0.5 1"/>
  	</material>


	<!-- BASE LINK --> 

	<link name="base_link">
		
	</link>
	
	<!-- BASE_FOOTPRINT LINK -->
 
	<joint name="base_footprint_joint" type="fixed">
		<parent link="base_link"/>
		<child link="base_footprint"/>
		<origin xyz="0 0 0" rpy="0 0 0"/> 
	</joint>
	
	<link name="base_footprint">
	
	</link>
	
	<!-- CHASSIS LINK -->	
	
	<joint name="chassis_joint" type="fixed">
		<parent link="base_link"/>
		<child link="chassis"/>
		<origin xyz="0 0 0" rpy="0 0 0"/> 
	</joint>
	
	<link name="chassis">
		<visual>
			<origin xyz="0 0 0.04"/>
			<geometry>
				<box size="0.3 0.28 0.08"/>
			</geometry>
			<material name="white"/>
		</visual>
		<collision>
			<origin xyz="0 0 0.04"/>
			<geometry>
				<box size="0.3 0.28 0.08"/>
			</geometry>
			<material name="white"/>
		</collision>
		<xacro:inertial_box mass="2" x="0.3" y="0.28" z="0.08">
			<origin xyz="0 0 0.04" rpy="0 0 0"/>
		</xacro:inertial_box>
	</link>
	
	<gazebo reference="chassis">
		<material>Gazebo/White</material>
	</gazebo>
	
	<!-- LEFT WHEEL LINK -->
	
	<!-- <joint name="left_wheel_joint" type="continuous">
		<parent link="chassis"/>
		<child link="left_wheel"/>
		<origin xyz="0 0.155 0" rpy="-${pi/2} 0 0"/>
		<axis xyz="0 0 1"/>
	</joint> -->

	<joint name="left_wheel_joint" type="continuous">
		<parent link="chassis"/>
		<child link="left_wheel"/>
		<origin xyz="0 0.155 0" rpy="-${pi/2} 0 0"/>
		<axis xyz="0 0 1"/>
		<dynamics damping="0.1" friction="0.1"/>
	</joint>
	
	<link name="left_wheel">
		<visual>
			<geometry>
				<cylinder radius="0.04" length="0.03"/>
			</geometry>
			<material name="blue"/>
		</visual>
		<collision>
			<geometry>
				<cylinder radius="0.04" length="0.03"/>
			</geometry>
			<material name="blue"/>
		</collision>
		<xacro:inertial_cylinder mass="0.5" radius="0.04" length="0.03">
			<origin xyz="0 0 0" rpy="0 0 0"/>
		</xacro:inertial_cylinder>
	</link>
	
	<!-- <gazebo reference="left_wheel">
		<material>Gazebo/Blue</material>
	</gazebo> -->
	
	<gazebo reference="left_wheel">
		<material>Gazebo/Blue</material>
		<mu1 value="1.0"/>
		<mu2 value="1.0"/>
		<kp value="1000000.0"/>
		<kd value="100.0"/>
		<minDepth value="0.001"/>
		<maxVel value="1.0"/>
	</gazebo>
	
	<!-- RIGHT WHEEL LINK -->
	
	<!-- <joint name="right_wheel_joint" type="continuous">
		<parent link="chassis"/>
		<child link="right_wheel"/>
		<origin xyz="0 -0.155 0" rpy="${pi/2} 0 0"/>
		<axis xyz="0 0 -1"/>
	</joint> -->
	
	<joint name="right_wheel_joint" type="continuous">
		<parent link="chassis"/>
		<child link="right_wheel"/>
		<origin xyz="0 -0.155 0" rpy="${pi/2} 0 0"/>
		<axis xyz="0 0 -1"/>
		<dynamics damping="0.1" friction="0.1"/>
	</joint>

	<link name="right_wheel">
		<visual>
			<geometry>
				<cylinder radius="0.04" length="0.03"/>
			</geometry>
			<material name="blue"/>
		</visual>
		<collision>
			<geometry>
				<cylinder radius="0.04" length="0.03"/>
			</geometry>
			<material name="blue"/>
		</collision>
		<xacro:inertial_cylinder mass="0.5" radius="0.04" length="0.03">
			<origin xyz="0 0 0" rpy="0 0 0"/>
		</xacro:inertial_cylinder>
	</link>
	
	<!-- <gazebo reference="right_wheel">
		<material>Gazebo/Blue</material>
	</gazebo> -->

	<gazebo reference="right_wheel">
		<material>Gazebo/Blue</material>
		<mu1 value="1.0"/>
		<mu2 value="1.0"/>
		<kp value="1000000.0"/>
		<kd value="100.0"/>
		<minDepth value="0.001"/>
		<maxVel value="1.0"/>
	</gazebo>
	
	<!-- CASTER WHEEL LINK BACK -->
	
	<joint name="caster_wheel_joint_back" type="fixed">
		<parent link="chassis"/>
		<child link="caster_wheel_back"/>
		<origin xyz="-0.1 0 0"/>
	</joint>
	
	<link name="caster_wheel_back">
		<visual>
			<geometry>
				<sphere radius="0.04"/>
			</geometry>
			<material name="black"/>
		</visual>
		<collision>
			<geometry>
				<sphere radius="0.04"/>
			</geometry>
			<material name="black"/>
		</collision>
		<xacro:inertial_sphere mass="0.1" radius="0.04">
			<origin xyz="0 0 0" rpy="0 0 0"/>
		</xacro:inertial_sphere>
	</link>
	
	<gazebo reference="caster_wheel_back">
		<material>Gazebo/Black</material>
		<mu1 value="0.1"/>
		<mu2 value="0.1"/>
	</gazebo>

	<!-- CASTER WHEEL LINK 2 -->
	
	<joint name="caster_wheel_joint_front" type="fixed">
		<parent link="chassis"/>
		<child link="caster_wheel_front"/>
		<origin xyz="0.1 0 0"/>
	</joint>
	
	<link name="caster_wheel_front">
		<visual>
			<geometry>
				<sphere radius="0.04"/>
			</geometry>
			<material name="black"/>
		</visual>
		<collision>
			<geometry>
				<sphere radius="0.04"/>
			</geometry>
			<material name="black"/>
		</collision>
		<xacro:inertial_sphere mass="0.1" radius="0.04">
			<origin xyz="0 0 0" rpy="0 0 0"/>
		</xacro:inertial_sphere>
	</link>
	
	<gazebo reference="caster_wheel_front">
		<material>Gazebo/Black</material>
		<mu1 value="0.1"/>
		<mu2 value="0.1"/>
	</gazebo>
		

</robot>
